[2024-01-23T16:51:21.885+0000] {taskinstance.py:1956} INFO - Dependencies all met for dep_context=non-requeueable deps ti=<TaskInstance: tutorial_dag.get_account scheduled__2024-01-23T15:30:00+00:00 [queued]>
[2024-01-23T16:51:21.896+0000] {taskinstance.py:1956} INFO - Dependencies all met for dep_context=requeueable deps ti=<TaskInstance: tutorial_dag.get_account scheduled__2024-01-23T15:30:00+00:00 [queued]>
[2024-01-23T16:51:21.897+0000] {taskinstance.py:2170} INFO - Starting attempt 1 of 1
[2024-01-23T16:51:21.916+0000] {taskinstance.py:2191} INFO - Executing <Task(PythonOperator): get_account> on 2024-01-23 15:30:00+00:00
[2024-01-23T16:51:21.936+0000] {standard_task_runner.py:60} INFO - Started process 1177 to run task
[2024-01-23T16:51:21.939+0000] {standard_task_runner.py:87} INFO - Running: ['***', 'tasks', 'run', 'tutorial_dag', 'get_account', 'scheduled__2024-01-23T15:30:00+00:00', '--job-id', '3', '--raw', '--subdir', 'DAGS_FOLDER/tutorial_dag.py', '--cfg-path', '/tmp/tmpnx7rw69y']
[2024-01-23T16:51:21.940+0000] {standard_task_runner.py:88} INFO - Job 3: Subtask get_account
[2024-01-23T16:51:21.997+0000] {task_command.py:423} INFO - Running <TaskInstance: tutorial_dag.get_account scheduled__2024-01-23T15:30:00+00:00 [running]> on host 825c5146cac7
[2024-01-23T16:51:22.095+0000] {taskinstance.py:2480} INFO - Exporting env vars: AIRFLOW_CTX_DAG_OWNER='***' AIRFLOW_CTX_DAG_ID='tutorial_dag' AIRFLOW_CTX_TASK_ID='get_account' AIRFLOW_CTX_EXECUTION_DATE='2024-01-23T15:30:00+00:00' AIRFLOW_CTX_TRY_NUMBER='1' AIRFLOW_CTX_DAG_RUN_ID='scheduled__2024-01-23T15:30:00+00:00'
[2024-01-23T16:51:24.845+0000] {taskinstance.py:2698} ERROR - Task failed with exception
Traceback (most recent call last):
  File "/home/airflow/.local/lib/python3.8/site-packages/airflow/models/taskinstance.py", line 433, in _execute_task
    result = execute_callable(context=context, **execute_callable_kwargs)
  File "/home/airflow/.local/lib/python3.8/site-packages/airflow/operators/python.py", line 199, in execute
    return_value = self.execute_callable()
  File "/home/airflow/.local/lib/python3.8/site-packages/airflow/operators/python.py", line 216, in execute_callable
    return self.python_callable(*self.op_args, **self.op_kwargs)
  File "/opt/airflow/dags/tutorial_dag.py", line 14, in get_account
    df = pd.DataFrame(json.load(response.content))
  File "/usr/local/lib/python3.8/json/__init__.py", line 293, in load
    return loads(fp.read(),
AttributeError: 'bytes' object has no attribute 'read'
[2024-01-23T16:51:24.960+0000] {taskinstance.py:1138} INFO - Marking task as FAILED. dag_id=tutorial_dag, task_id=get_account, execution_date=20240123T153000, start_date=20240123T165121, end_date=20240123T165124
[2024-01-23T16:51:25.132+0000] {standard_task_runner.py:107} ERROR - Failed to execute job 3 for task get_account ('bytes' object has no attribute 'read'; 1177)
[2024-01-23T16:51:25.203+0000] {local_task_job_runner.py:234} INFO - Task exited with return code 1
[2024-01-23T16:51:25.231+0000] {taskinstance.py:3280} INFO - 0 downstream tasks scheduled from follow-on schedule check
